<?xml version="1.0" ?>
<robot name="assembly" xmlns:xacro="http://www.ros.org/wiki/xacro">

<xacro:include filename="$(find assembly_description)/urdf/materials.xacro" />
<xacro:include filename="$(find assembly_description)/urdf/assembly.trans" />
<xacro:include filename="$(find assembly_description)/urdf/assembly.gazebo" />

<link name="dummy">
   </link>
  <link name="base_link">
    <inertial>
      <origin xyz="0.0 0.0 0.098" rpy="0 0 0"/>
      <mass value="129.39626"/>
      <inertia ixx="1.321093" iyy="1.321093" izz="1.813704" ixy="0.0" iyz="0.0" ixz="0.0"/>
    </inertial>
    <visual>
      <origin xyz="0 0 0" rpy="0 0 0"/>
      <geometry>
        <mesh filename="package://assembly_description/meshes/base_link.stl" scale="0.001 0.001 0.001"/>
      </geometry>
      <material name="orange"/>
    </visual>
    <collision>
      <origin xyz="0 0 0" rpy="0 0 0"/>
      <geometry>
        <mesh filename="package://assembly_description/meshes/base_link.stl" scale="0.001 0.001 0.001"/>
      </geometry>
    </collision>
  </link>
  <joint name="dummy_joint" type="fixed">
     <parent link="dummy"/>
     <child link="base_link"/>
   </joint>

<link name="vertical_link_1">
  <inertial>
    <origin xyz="0.018670956454225448 0.0 0.3432285363372299" rpy="0 0 0"/>
    <mass value="11.54357574173566"/>
    <inertia ixx="0.731551" iyy="0.737167" izz="0.012695" ixy="-0.0" iyz="0.0" ixz="-0.012883"/>
  </inertial>
  <visual>
    <origin xyz="-0.0 -0.0 -0.196" rpy="0 0 0"/>
    <geometry>
      <mesh filename="package://assembly_description/meshes/vertical_link_1.stl" scale="0.001 0.001 0.001"/>
    </geometry>
    <material name="orange"/>
  </visual>
  <collision>
    <origin xyz="-0.0 -0.0 -0.196" rpy="0 0 0"/>
    <geometry>
      <mesh filename="package://assembly_description/meshes/vertical_link_1.stl" scale="0.001 0.001 0.001"/>
    </geometry>
  </collision>
</link>

<link name="arm_link_1_1">
  <inertial>
    <origin xyz="-0.032387523353649084 1.549768176563408e-17 -0.19899999999999995" rpy="0 0 0"/>
    <mass value="1.2178346565486904"/>
    <inertia ixx="0.000766" iyy="0.001022" izz="0.00104" ixy="0.0" iyz="0.0" ixz="0.0"/>
  </inertial>
  <visual>
    <origin xyz="0.018 -0.0 -0.798" rpy="0 0 0"/>
    <geometry>
      <mesh filename="package://assembly_description/meshes/arm_link_1_1.stl" scale="0.001 0.001 0.001"/>
    </geometry>
    <material name="orange"/>
  </visual>
  <collision>
    <origin xyz="0.018 -0.0 -0.798" rpy="0 0 0"/>
    <geometry>
      <mesh filename="package://assembly_description/meshes/arm_link_1_1.stl" scale="0.001 0.001 0.001"/>
    </geometry>
  </collision>
</link>

<link name="arm_link_2_1">
  <inertial>
    <origin xyz="-0.05397205909811591 2.3238019347110366e-16 -0.02124999999999988" rpy="0 0 0"/>
    <mass value="3.222674042197021"/>
    <inertia ixx="0.001386" iyy="0.009534" izz="0.009779" ixy="0.0" iyz="-0.0" ixz="-0.0"/>
  </inertial>
  <visual>
    <origin xyz="0.104 -0.0 -0.62025" rpy="0 0 0"/>
    <geometry>
      <mesh filename="package://assembly_description/meshes/arm_link_2_1.stl" scale="0.001 0.001 0.001"/>
    </geometry>
    <material name="orange"/>
  </visual>
  <collision>
    <origin xyz="0.104 -0.0 -0.62025" rpy="0 0 0"/>
    <geometry>
      <mesh filename="package://assembly_description/meshes/arm_link_2_1.stl" scale="0.001 0.001 0.001"/>
    </geometry>
  </collision>
</link>

<link name="arm_link_3_1">
  <inertial>
    <origin xyz="-0.11320407936321158 6.299809973410066e-16 -0.02124999999999988" rpy="0 0 0"/>
    <mass value="5.232567258847803"/>
    <inertia ixx="0.002007" iyy="0.041392" izz="0.041824" ixy="0.0" iyz="0.0" ixz="-0.0"/>
  </inertial>
  <visual>
    <origin xyz="0.269296 -0.0 -0.62025" rpy="0 0 0"/>
    <geometry>
      <mesh filename="package://assembly_description/meshes/arm_link_3_1.stl" scale="0.001 0.001 0.001"/>
    </geometry>
    <material name="orange"/>
  </visual>
  <collision>
    <origin xyz="0.269296 -0.0 -0.62025" rpy="0 0 0"/>
    <geometry>
      <mesh filename="package://assembly_description/meshes/arm_link_3_1.stl" scale="0.001 0.001 0.001"/>
    </geometry>
  </collision>
</link>

<link name="end_effector_1">
  <inertial>
    <origin xyz="2.8481853986406236e-08 9.019370285038243e-16 -0.03405861479141403" rpy="0 0 0"/>
    <mass value="0.5819246240608114"/>
    <inertia ixx="0.000318" iyy="0.000318" izz="0.000413" ixy="-0.0" iyz="0.0" ixz="0.0"/>
  </inertial>
  <visual>
    <origin xyz="0.514296 -0.0 -0.57775" rpy="0 0 0"/>
    <geometry>
      <mesh filename="package://assembly_description/meshes/end_effector_1.stl" scale="0.001 0.001 0.001"/>
    </geometry>
    <material name="orange"/>
  </visual>
  <collision>
    <origin xyz="0.514296 -0.0 -0.57775" rpy="0 0 0"/>
    <geometry>
      <mesh filename="package://assembly_description/meshes/end_effector_1.stl" scale="0.001 0.001 0.001"/>
    </geometry>
  </collision>
</link>

<joint name="Rev1" type="continuous">
  <origin xyz="0.0 0.0 0.196" rpy="0 0 0"/>
  <parent link="base_link"/>
  <child link="vertical_link_1"/>
  <axis xyz="0.0 0.0 1.0"/>
  <limit upper="1.57" lower="-1.57" effort="100" velocity="0.1"/>
  <dynamics damping="0.7" friction="10.0"/>
</joint>

<joint name="Slider2" type="prismatic">
  <origin xyz="-0.018 0.0 0.602" rpy="0 0 0"/>
  <parent link="vertical_link_1"/>
  <child link="arm_link_1_1"/>
  <axis xyz="0.0 0.0 1.0"/>
  <limit upper="0.3" lower="-0.3" effort="100" velocity="0.1"/>
  <dynamics damping="0.1" friction="10.0"/>
</joint>

<joint name="Rev3" type="continuous">
  <origin xyz="-0.086 0.0 -0.17775" rpy="0 0 0"/>
  <parent link="arm_link_1_1"/>
  <child link="arm_link_2_1"/>
  <axis xyz="0.0 0.0 -1.0"/>
  <limit upper="1.57" lower="-1.57" effort="100" velocity="0.1"/>
  <dynamics damping="0.1" friction="10.0"/>
</joint>

<joint name="Rev4" type="continuous">
  <origin xyz="-0.165296 0.0 0.0" rpy="0 0 0"/>
  <parent link="arm_link_2_1"/>
  <child link="arm_link_3_1"/>
  <axis xyz="-0.0 0.0 -1.0"/>
  <limit upper="1.57" lower="-1.57" effort="100" velocity="0.1"/>
  <dynamics damping="0.1" friction="10.0"/>
</joint>

<joint name="Rev5" type="continuous">
  <origin xyz="-0.245 0.0 -0.0425" rpy="0 0 0"/>
  <parent link="arm_link_3_1"/>
  <child link="end_effector_1"/>
  <axis xyz="0.0 0.0 -1.0"/>
  <limit upper="1.57" lower="-1.57" effort="100" velocity="0.1"/>
  <dynamics damping="0.1" friction="10.0"/>
</joint>

<scene>
  <ambient>0.4 0.4 0.4 1</ambient>
  <background>0.7 0.7 0.7 1</background>
  <shadows>0</shadows>
</scene>

</robot>
